Workbook

Sheet Q
C1: آزمون شخصیت شناسی MBTI
A2: نام و نام خانوادگی: | D2: رضا امیرخانی
A3: تاریخ تولد: | D3: =NOW() -> 46103.047
A4: پایه و کلاس: | D4: 10.2
A5: جنس: | D5: مرد / زن
C6: پاسخگوی گرامی؛ هر یک از عبارات زیر را به دقت بخوانید و مشخص کنید کدام یک از عبارات شما را بهتر توصیف می‌کند. جلوی همان عبارت عدد «1» بگذارید. | F6: نظر شما
C8: 1 | D8: الف: معمولاً احساسات و عواطف خود را در خویش نگه می دارم.
D9: ب: معمولاً احساسات و عواطف خودرا با دیگران و به راحتی درمیان می گذارم.
C11: 2 | D11: الف: برای من امور قطعی، عینی و مشخص مهم هستند.
D12: ب: برای من ایده ها، استنباط ها و الهامات مهم هستند.
C14: 3 | D14: الف: هنگام تصمیم گیری به آنچه که منطق و خرد بر آن حکم می کند، عمل می کنم.
D15: ب: هنگام تصمیم گیری به آنچه که احساسات و دلم گواه می دهد، عمل می کنم.
C17: 4 | D17: الف: دوست دارم در شرایط انعطاف پذیر و متغیری زندگی کنم.
D18: ب: دوست دارم همه چیز منظم و برنامه ریزی شده باشد.
C20: 5 | D20: الف: دوست دارم در زمینه های محدودی اطلاعات داشته باشم ولی در هر زمینه عمیق و کامل.
D21: ب: دوست دارم در زمینه های زیادی اطلاعات داشته باشم ولی در هر زمینه تا حد کم و سطحی.
C23: 6 | D23: الف: بیشتر اوقات به واقعیات عینی (آنچه که وجود دارد ) توجه می کنم.
D24: ب: بیشتر اوقات حقایق ( آنچه که باید وجود داشته باشد ) را در ذهن و تخیل خود مجسم می کنم.
C26: 7 | D26: الف: از نظر من یک قاضی و داور عادل برای جامعه مفیدتر است.
D27: ب: از نظر من یک معلم و مربی مهربان برای جامعه مفیدتر است.
C29: 8 | D29: الف: ترجیحاً ملاقاتها و دیدارهای خود را بدون برنامه قبلی و آزادانه انجام می دهم.
D30: ب:: ترجیحاً دیدار با افراد و وعده ملاقات خود را از پیش تعیین می کنم.
C32: 9 | D32: الف: کم حرف و محتاط هستم و علاقه ای به جلب توجه دیگران به خود ندارم.
D33: ب: توجه دیگران را به خود جلب می کنم.
C35: 10 | D35: الف: اگر معلم بودم ترجیح می دادم دروسی را تدریس کنم که واقعیات و امور قطعی وعینی را شامل شوند. (مانند جغرافیا)
D36: ب: اگر معلم بودم، ترجیحاً دروسی را تدریس می کردم که حقایق و نظریه ها و تئوری ها را شامل شوند. (مانند فلسفه)
C38: 11 | D38: الف: قاطع، محکم و استوار هستم.
D39: ب: انعطاف پذیر، ملایم و لطیف هستم.
C41: 12 | D41: الف: غالباً انجام کارهای پیش پا افتاده و جزئی را فراموش می کنم.
D42: ب: به منظور جلوگیری از فراموش شدن انجام کارها، آن ها را یادداشت می کنم.
C44: 13 | D44: الف: در مهمانی ها، جلسات وگردهمایی ها منتظر می مانم تا دیگران به سوی من بیایند.
D45: ب: در مهمانی ها، جلسات وگردهمایی ها من سر صحبت را با دیگران باز می کنم.
C47: 14 | D47: الف: به جزئیات امور توجه زیادی دارم.
D48: ب: بیشتر کلیت هر موضوعی برایم مهم است و به جزئیات آن توجه زیادی نمی کنم.
C50: 15 | D50: الف: به آینده اهمیت زیادی داده و برای آن برنامه ریزی می کنم.
D51: ب: خیلی به آینده فکر نمی کنم.
C53: 16 | D53: الف: معمولاً کارها را شروع می کنم و حین اجرا به رفع اشکالات اجرایی وتدارک مورد نیاز می پردازم.
D54: ب: قبل از اجرای طرح ها وکارها برنامه ریزی انجام می دهم.
C56: 17 | D56: الف: مایل هستم دوستان کم همراه با ارتباط زیاد و صمیمانه داشته باشم.
D57: ب: مایل هستم دوستان زیاد همراه با ارتباط محدود داشته باشم.
...

Sheet Process
B2: Q-Num | C2: الف | D2: ب
B3: 1 | C3: =Q!F8 -> 0 | D3: =Q!F9 -> 0 | F3: I / E | G3: S / N | H3: T / F | I3: J / P
B4: 2 | C4: =Q!F11 -> 0 | D4: =Q!F12 -> 0 | F4: =(C3+C7+C11+C15+C19+C23+C27+C31+C35+C39+C43+C47+C51+C55+C59) -> 0 | G4: =(C4+C8+C12+C16+C20+C24+C28+C32+C36+C40+C44+C48+C52+C56+C60) -> 0 | H4: =(C5+C9+C13+C17+C21+C25+C29+C33+C37+C41+C45+C49+C53+C57+C61) -> 0 | I4: =(D6+D10+D14+D18+D22+D26+D30+D34+D38+D42+D46+D50+D54+D58+D62) -> 0
B5: 3 | C5: =Q!F14 -> 0 | D5: =Q!F15 -> 0 | F5: =15-F$4 -> 15 | G5: =15-G$4 -> 15 | H5: =15-H$4 -> 15 | I5: =15-I$4 -> 15
B6: 4 | C6: =Q!F17 -> 0 | D6: =Q!F18 -> 0 | F6: I | G6: S | H6: T | I6: J
B7: 5 | C7: =Q!F20 -> 0 | D7: =Q!F21 -> 0 | F7: E | G7: N | H7: F | I7: P
B8: 6 | C8: =Q!F23 -> 0 | D8: =Q!F24 -> 0 | F8: =IF(F4>7.5,F6,F7) -> E | G8: =IF(G4>7.5,G6,G7) -> N | H8: =IF(H4>7.5,H6,H7) -> F | I8: =IF(I4>7.5,I6,I7) -> P
B9: 7 | C9: =Q!F26 -> 0 | D9: =Q!F27 -> 0
B10: 8 | C10: =Q!F29 -> 0 | D10: =Q!F30 -> 0
B11: 9 | C11: =Q!F32 -> 0 | D11: =Q!F33 -> 0
B12: 10 | C12: =Q!F35 -> 0 | D12: =Q!F36 -> 0
B13: 11 | C13: =Q!F38 -> 0 | D13: =Q!F39 -> 0
B14: 12 | C14: =Q!F41 -> 0 | D14: =Q!F42 -> 0
B15: 13 | C15: =Q!F44 -> 0 | D15: =Q!F45 -> 0
B16: 14 | C16: =Q!F47 -> 0 | D16: =Q!F48 -> 0
B17: 15 | C17: =Q!F50 -> 0 | D17: =Q!F51 -> 0
B18: 16 | C18: =Q!F53 -> 0 | D18: =Q!F54 -> 0
B19: 17 | C19: =Q!F56 -> 0 | D19: =Q!F57 -> 0
B20: 18 | C20: =Q!F59 -> 0 | D20: =Q!F60 -> 0
B21: 19 | C21: =Q!F62 -> 0 | D21: =Q!F63 -> 0
B22: 20 | C22: =Q!F65 -> 0 | D22: =Q!F66 -> 0
B23: 21 | C23: =Q!F68 -> 0 | D23: =Q!F69 -> 0
B24: 22 | C24: =Q!F71 -> 0 | D24: =Q!F72 -> 0
B25: 23 | C25: =Q!F74 -> 0 | D25: =Q!F75 -> 0
B26: 24 | C26: =Q!F77 -> 0 | D26: =Q!F78 -> 0
B27: 25 | C27: =Q!F80 -> 0 | D27: =Q!F81 -> 0
B28: 26 | C28: =Q!F83 -> 0 | D28: =Q!F84 -> 0
B29: 27 | C29: =Q!F86 -> 0 | D29: =Q!F87 -> 0
B30: 28 | C30: =Q!F89 -> 0 | D30: =Q!F90 -> 0
B31: 29 | C31: =Q!F92 -> 0 | D31: =Q!F93 -> 0
B32: 30 | C32: =Q!F95 -> 0 | D32: =Q!F96 -> 0
B33: 31 | C33: =Q!F98 -> 0 | D33: =Q!F99 -> 0
B34: 32 | C34: =Q!F101 -> 0 | D34: =Q!F102 -> 0
B35: 33 | C35: =Q!F104 -> 0 | D35: =Q!F105 -> 0
B36: 34 | C36: =Q!F107 -> 0 | D36: =Q!F108 -> 0
B37: 35 | C37: =Q!F110 -> 0 | D37: =Q!F111 -> 0
B38: 36 | C38: =Q!F113 -> 0 | D38: =Q!F114 -> 0
B39: 37 | C39: =Q!F116 -> 0 | D39: =Q!F117 -> 0
B40: 38 | C40: =Q!F119 -> 0 | D40: =Q!F120 -> 0
B41: 39 | C41: =Q!F122 -> 0 | D41: =Q!F123 -> 0
...

Sheet Concat
D5: تیپ شخصیتی شما | E5: =Process!$F$8 & Process!$G$8 & Process!$H$8 & Process!$I$8 -> ENFP | F5: است.

Sheet D
A1: Name | B1: Grade | C1: I-E | D1: S-N | E1: T-F | F1: J-P | G1: Type
A2: سعید محمدی | B2: 10.1 | C2: 12 | D2: 12 | E2: 14 | F2: 6 | G2: =IF(Table1[[#This Row],[I-E]]>7.5,"I","E") & IF(Table1[[#This Row],[S-N]]>7.5,"S","N") & IF(Table1[[#This Row],[T-F]]>7.5,"T","F") & IF(Table1[[#This Row],[J-P]]>7.5,"J","P") -> ISTP
A3: شایان مرادی | B3: 10.1 | C3: 2 | D3: 5 | E3: 5 | F3: 11 | G3: =IF(Table1[[#This Row],[I-E]]>7.5,"I","E") & IF(Table1[[#This Row],[S-N]]>7.5,"S","N") & IF(Table1[[#This Row],[T-F]]>7.5,"T","F") & IF(Table1[[#This Row],[J-P]]>7.5,"J","P") -> ENFJ
A4: قدیر شادکام | B4: 10.1 | C4: 12 | D4: 6 | E4: 13 | F4: 1 | G4: =IF(Table1[[#This Row],[I-E]]>7.5,"I","E") & IF(Table1[[#This Row],[S-N]]>7.5,"S","N") & IF(Table1[[#This Row],[T-F]]>7.5,"T","F") & IF(Table1[[#This Row],[J-P]]>7.5,"J","P") -> INTP
A5: محراب کاظم لو | B5: 10.1 | C5: 14 | D5: 10 | E5: 14 | F5: 9 | G5: =IF(Table1[[#This Row],[I-E]]>7.5,"I","E") & IF(Table1[[#This Row],[S-N]]>7.5,"S","N") & IF(Table1[[#This Row],[T-F]]>7.5,"T","F") & IF(Table1[[#This Row],[J-P]]>7.5,"J","P") -> ISTJ
A6: محمد زمانی | B6: 10.1 | C6: 8 | D6: 7 | E6: 14 | F6: 10 | G6: =IF(Table1[[#This Row],[I-E]]>7.5,"I","E") & IF(Table1[[#This Row],[S-N]]>7.5,"S","N") & IF(Table1[[#This Row],[T-F]]>7.5,"T","F") & IF(Table1[[#This Row],[J-P]]>7.5,"J","P") -> INTJ
A7: محمد علی آبادی | B7: 10.1 | C7: 9 | D7: 10 | E7: 13 | F7: 2 | G7: =IF(Table1[[#This Row],[I-E]]>7.5,"I","E") & IF(Table1[[#This Row],[S-N]]>7.5,"S","N") & IF(Table1[[#This Row],[T-F]]>7.5,"T","F") & IF(Table1[[#This Row],[J-P]]>7.5,"J","P") -> ISTP
A8: محمد مهدی گل افشان | B8: 9.1 | C8: 7 | D8: 4 | E8: 11 | F8: 6 | G8: =IF(Table1[[#This Row],[I-E]]>7.5,"I","E") & IF(Table1[[#This Row],[S-N]]>7.5,"S","N") & IF(Table1[[#This Row],[T-F]]>7.5,"T","F") & IF(Table1[[#This Row],[J-P]]>7.5,"J","P") -> ENTP
A9: محمد رضا بیابانی | B9: 9.1 | C9: 7 | D9: 5 | E9: 12 | F9: 4 | G9: =IF(Table1[[#This Row],[I-E]]>7.5,"I","E") & IF(Table1[[#This Row],[S-N]]>7.5,"S","N") & IF(Table1[[#This Row],[T-F]]>7.5,"T","F") & IF(Table1[[#This Row],[J-P]]>7.5,"J","P") -> ENTP
A10: محمدرضا مشهد نعمتی | B10: 9.1 | C10: 12 | D10: 5 | E10: 9 | F10: 3 | G10: =IF(Table1[[#This Row],[I-E]]>7.5,"I","E") & IF(Table1[[#This Row],[S-N]]>7.5,"S","N") & IF(Table1[[#This Row],[T-F]]>7.5,"T","F") & IF(Table1[[#This Row],[J-P]]>7.5,"J","P") -> INTP
A11: محمد پورقلی زاده | B11: 8.1 | C11: 10 | D11: 5 | E11: 6 | F11: 4 | G11: =IF(Table1[[#This Row],[I-E]]>7.5,"I","E") & IF(Table1[[#This Row],[S-N]]>7.5,"S","N") & IF(Table1[[#This Row],[T-F]]>7.5,"T","F") & IF(Table1[[#This Row],[J-P]]>7.5,"J","P") -> INFP
A12: محمد رستمی | B12: 8.1 | C12: 12 | D12: 5 | E12: 14 | F12: 3 | G12: =IF(Table1[[#This Row],[I-E]]>7.5,"I","E") & IF(Table1[[#This Row],[S-N]]>7.5,"S","N") & IF(Table1[[#This Row],[T-F]]>7.5,"T","F") & IF(Table1[[#This Row],[J-P]]>7.5,"J","P") -> INTP
A13: ابراهیم ابراهیمی | B13: 8.1 | C13: 14 | D13: 6 | E13: 14 | F13: 10 | G13: =IF(Table1[[#This Row],[I-E]]>7.5,"I","E") & IF(Table1[[#This Row],[S-N]]>7.5,"S","N") & IF(Table1[[#This Row],[T-F]]>7.5,"T","F") & IF(Table1[[#This Row],[J-P]]>7.5,"J","P") -> INTJ
... A29: مهدی رحیمی | B29: 8.1 | C29: 7 | D29: 7 | E29: 15 | F29: 8 | G29: =IF(Table1[[#This Row],[I-E]]>7.5,"I","E") & IF(Table1[[#This Row],[S-N]]>7.5,"S","N") & IF(Table1[[#This Row],[T-F]]>7.5,"T","F") & IF(Table1[[#This Row],[J-P]]>7.5,"J","P") -> ENTJ
A30: ali | B30: 7.1 | C30: 1 | D30: 1 | E30: 1 | F30: 0 | G30: ENFP
A31: =SUBTOTAL(103,Table1[Name]) -> 29 | C31: =SUBTOTAL(101,Table1[I-E]) -> 9.1724138 | D31: =SUBTOTAL(101,Table1[S-N]) -> 7.2068966 | E31: =SUBTOTAL(101,Table1[T-F]) -> 10 | F31: =SUBTOTAL(101,Table1[J-P]) -> 7

Sheet Result
A1: # | B1: Name | C1: Grade | D1: I-E | E1: S-N | F1: T-F | G1: J-P | H1: Type
A2: 9501 | B2: سعید محمدی | C2: 10 | D2: 12 | E2: 12 | F2: 14 | G2: 6 | H2: =IF(ResultTable[[#This Row],[I-E]]>7.5,"I","E") & IF(ResultTable[[#This Row],[S-N]]>7.5,"S","N") & IF(ResultTable[[#This Row],[T-F]]>7.5,"T","F") & IF(ResultTable[[#This Row],[J-P]]>7.5,"J","P") -> ISTP
A3: 9502 | B3: شایان مرادی | C3: 10 | D3: 2 | E3: 5 | F3: 5 | G3: 11 | H3: =IF(ResultTable[[#This Row],[I-E]]>7.5,"I","E") & IF(ResultTable[[#This Row],[S-N]]>7.5,"S","N") & IF(ResultTable[[#This Row],[T-F]]>7.5,"T","F") & IF(ResultTable[[#This Row],[J-P]]>7.5,"J","P") -> ENFJ
A4: 9503 | B4: قدیر شادکام | C4: 10 | D4: 12 | E4: 6 | F4: 13 | G4: 1 | H4: =IF(ResultTable[[#This Row],[I-E]]>7.5,"I","E") & IF(ResultTable[[#This Row],[S-N]]>7.5,"S","N") & IF(ResultTable[[#This Row],[T-F]]>7.5,"T","F") & IF(ResultTable[[#This Row],[J-P]]>7.5,"J","P") -> INTP
A5: 9504 | B5: محراب کاظم لو | C5: 10 | D5: 14 | E5: 10 | F5: 14 | G5: 9 | H5: =IF(ResultTable[[#This Row],[I-E]]>7.5,"I","E") & IF(ResultTable[[#This Row],[S-N]]>7.5,"S","N") & IF(ResultTable[[#This Row],[T-F]]>7.5,"T","F") & IF(ResultTable[[#This Row],[J-P]]>7.5,"J","P") -> ISTJ
A6: 9505 | B6: محمد زمانی | C6: 10 | D6: 8 | E6: 7 | F6: 14 | G6: 10 | H6: =IF(ResultTable[[#This Row],[I-E]]>7.5,"I","E") & IF(ResultTable[[#This Row],[S-N]]>7.5,"S","N") & IF(ResultTable[[#This Row],[T-F]]>7.5,"T","F") & IF(ResultTable[[#This Row],[J-P]]>7.5,"J","P") -> INTJ
A7: 9506 | B7: محمد علی آبادی | C7: 10 | D7: 9 | E7: 10 | F7: 13 | G7: 2 | H7: =IF(ResultTable[[#This Row],[I-E]]>7.5,"I","E") & IF(ResultTable[[#This Row],[S-N]]>7.5,"S","N") & IF(ResultTable[[#This Row],[T-F]]>7.5,"T","F") & IF(ResultTable[[#This Row],[J-P]]>7.5,"J","P") -> ISTP
A8: 9601 | B8: محمد مهدی گل افشان | C8: 9 | D8: 7 | E8: 4 | F8: 11 | G8: 6 | H8: =IF(ResultTable[[#This Row],[I-E]]>7.5,"I","E") & IF(ResultTable[[#This Row],[S-N]]>7.5,"S","N") & IF(ResultTable[[#This Row],[T-F]]>7.5,"T","F") & IF(ResultTable[[#This Row],[J-P]]>7.5,"J","P") -> ENTP
A9: 9602 | B9: محمد رضا بیابانی | C9: 9 | D9: 7 | E9: 5 | F9: 12 | G9: 4 | H9: =IF(ResultTable[[#This Row],[I-E]]>7.5,"I","E") & IF(ResultTable[[#This Row],[S-N]]>7.5,"S","N") & IF(ResultTable[[#This Row],[T-F]]>7.5,"T","F") & IF(ResultTable[[#This Row],[J-P]]>7.5,"J","P") -> ENTP
A10: 9603 | B10: محمدرضا مشهد نعمتی | C10: 9 | D10: 12 | E10: 5 | F10: 9 | G10: 3 | H10: =IF(ResultTable[[#This Row],[I-E]]>7.5,"I","E") & IF(ResultTable[[#This Row],[S-N]]>7.5,"S","N") & IF(ResultTable[[#This Row],[T-F]]>7.5,"T","F") & IF(ResultTable[[#This Row],[J-P]]>7.5,"J","P") -> INTP
A11: 9701 | B11: محمد پورقلی زاده | C11: 8 | D11: 10 | E11: 5 | F11: 6 | G11: 4 | H11: =IF(ResultTable[[#This Row],[I-E]]>7.5,"I","E") & IF(ResultTable[[#This Row],[S-N]]>7.5,"S","N") & IF(ResultTable[[#This Row],[T-F]]>7.5,"T","F") & IF(ResultTable[[#This Row],[J-P]]>7.5,"J","P") -> INFP
A12: 9702 | B12: محمد رستمی | C12: 8 | D12: 12 | E12: 5 | F12: 14 | G12: 3 | H12: =IF(ResultTable[[#This Row],[I-E]]>7.5,"I","E") & IF(ResultTable[[#This Row],[S-N]]>7.5,"S","N") & IF(ResultTable[[#This Row],[T-F]]>7.5,"T","F") & IF(ResultTable[[#This Row],[J-P]]>7.5,"J","P") -> INTP
A13: 9703 | B13: ابراهیم ابراهیمی | C13: 8 | D13: 14 | E13: 6 | F13: 14 | G13: 10 | H13: =IF(ResultTable[[#This Row],[I-E]]>7.5,"I","E") & IF(ResultTable[[#This Row],[S-N]]>7.5,"S","N") & IF(ResultTable[[#This Row],[T-F]]>7.5,"T","F") & IF(ResultTable[[#This Row],[J-P]]>7.5,"J","P") -> INTJ
... A29: 9719 | B29: مهدی رحیمی | C29: 8 | D29: 7 | E29: 7 | F29: 15 | G29: 8 | H29: =IF(ResultTable[[#This Row],[I-E]]>7.5,"I","E") & IF(ResultTable[[#This Row],[S-N]]>7.5,"S","N") & IF(ResultTable[[#This Row],[T-F]]>7.5,"T","F") & IF(ResultTable[[#This Row],[J-P]]>7.5,"J","P") -> ENTJ
B30: =SUBTOTAL(103,ResultTable[Name]) -> 28 | D30: =SUBTOTAL(101,ResultTable[I-E]) -> 9.4642857 | E30: =SUBTOTAL(101,ResultTable[S-N]) -> 7.4285714 | F30: =SUBTOTAL(101,ResultTable[T-F]) -> 10.321429 | G30: =SUBTOTAL(101,ResultTable[J-P]) -> 7.25
